<?xml version="1.0"?>
<sdf version="1.9">
  <model name="nexus_quadcopter">
    <pose>0 0 0.2 0 0 0</pose>

    <!-- ── Base link (central body) ─────────────────────────────────── -->
    <link name="base_link">
      <inertial>
        <mass>1.5</mass>
        <inertia>
          <ixx>0.029125</ixx>
          <iyy>0.029125</iyy>
          <izz>0.055225</izz>
          <ixy>0</ixy><ixz>0</ixz><iyz>0</iyz>
        </inertia>
      </inertial>

      <!-- Central body -->
      <collision name="body_collision">
        <geometry>
          <box><size>0.25 0.25 0.08</size></box>
        </geometry>
      </collision>
      <visual name="body_visual">
        <geometry>
          <box><size>0.25 0.25 0.08</size></box>
        </geometry>
        <material>
          <ambient>0.2 0.2 0.2 1</ambient>
          <diffuse>0.3 0.3 0.3 1</diffuse>
          <specular>0.1 0.1 0.1 1</specular>
        </material>
      </visual>

      <!-- Arms -->
      <visual name="arm_fr">
        <pose>0.13 -0.13 0 0 0 -0.785</pose>
        <geometry><box><size>0.3 0.03 0.02</size></box></geometry>
        <material>
          <ambient>0.6 0.1 0.1 1</ambient>
          <diffuse>0.8 0.15 0.15 1</diffuse>
        </material>
      </visual>
      <visual name="arm_fl">
        <pose>0.13 0.13 0 0 0 0.785</pose>
        <geometry><box><size>0.3 0.03 0.02</size></box></geometry>
        <material>
          <ambient>0.6 0.1 0.1 1</ambient>
          <diffuse>0.8 0.15 0.15 1</diffuse>
        </material>
      </visual>
      <visual name="arm_rl">
        <pose>-0.13 0.13 0 0 0 -0.785</pose>
        <geometry><box><size>0.3 0.03 0.02</size></box></geometry>
        <material>
          <ambient>0.1 0.1 0.1 1</ambient>
          <diffuse>0.15 0.15 0.15 1</diffuse>
        </material>
      </visual>
      <visual name="arm_rr">
        <pose>-0.13 -0.13 0 0 0 0.785</pose>
        <geometry><box><size>0.3 0.03 0.02</size></box></geometry>
        <material>
          <ambient>0.1 0.1 0.1 1</ambient>
          <diffuse>0.15 0.15 0.15 1</diffuse>
        </material>
      </visual>

      <!-- Landing gear legs -->
      <visual name="leg_fl">
        <pose>0.1 0.1 -0.08 0 0 0</pose>
        <geometry><cylinder><radius>0.005</radius><length>0.12</length></cylinder></geometry>
        <material><ambient>0.3 0.3 0.3 1</ambient><diffuse>0.4 0.4 0.4 1</diffuse></material>
      </visual>
      <visual name="leg_fr">
        <pose>0.1 -0.1 -0.08 0 0 0</pose>
        <geometry><cylinder><radius>0.005</radius><length>0.12</length></cylinder></geometry>
        <material><ambient>0.3 0.3 0.3 1</ambient><diffuse>0.4 0.4 0.4 1</diffuse></material>
      </visual>
      <visual name="leg_rl">
        <pose>-0.1 0.1 -0.08 0 0 0</pose>
        <geometry><cylinder><radius>0.005</radius><length>0.12</length></cylinder></geometry>
        <material><ambient>0.3 0.3 0.3 1</ambient><diffuse>0.4 0.4 0.4 1</diffuse></material>
      </visual>
      <visual name="leg_rr">
        <pose>-0.1 -0.1 -0.08 0 0 0</pose>
        <geometry><cylinder><radius>0.005</radius><length>0.12</length></cylinder></geometry>
        <material><ambient>0.3 0.3 0.3 1</ambient><diffuse>0.4 0.4 0.4 1</diffuse></material>
      </visual>

      <!-- ── IMU sensor ──────────────────────────────────────────────── -->
      <sensor name="imu_sensor" type="imu">
        <always_on>true</always_on>
        <update_rate>250</update_rate>
        <imu>
          <angular_velocity>
            <x><noise type="gaussian">
              <mean>0.0</mean><stddev>0.0002</stddev>
              <bias_mean>0.0</bias_mean><bias_stddev>0.00004</bias_stddev>
            </noise></x>
            <y><noise type="gaussian">
              <mean>0.0</mean><stddev>0.0002</stddev>
              <bias_mean>0.0</bias_mean><bias_stddev>0.00004</bias_stddev>
            </noise></y>
            <z><noise type="gaussian">
              <mean>0.0</mean><stddev>0.0002</stddev>
              <bias_mean>0.0</bias_mean><bias_stddev>0.00004</bias_stddev>
            </noise></z>
          </angular_velocity>
          <linear_acceleration>
            <x><noise type="gaussian">
              <mean>0.0</mean><stddev>0.004</stddev>
              <bias_mean>0.0</bias_mean><bias_stddev>0.0006</bias_stddev>
            </noise></x>
            <y><noise type="gaussian">
              <mean>0.0</mean><stddev>0.004</stddev>
              <bias_mean>0.0</bias_mean><bias_stddev>0.0006</bias_stddev>
            </noise></y>
            <z><noise type="gaussian">
              <mean>0.0</mean><stddev>0.004</stddev>
              <bias_mean>0.0</bias_mean><bias_stddev>0.0006</bias_stddev>
            </noise></z>
          </linear_acceleration>
        </imu>
        <topic>imu</topic>
      </sensor>

      <!-- ── GPS / NavSat sensor ─────────────────────────────────────── -->
      <sensor name="navsat_sensor" type="navsat">
        <always_on>true</always_on>
        <update_rate>10</update_rate>
        <navsat>
          <position_sensing>
            <horizontal><noise type="gaussian">
              <mean>0.0</mean><stddev>0.5</stddev>
            </noise></horizontal>
            <vertical><noise type="gaussian">
              <mean>0.0</mean><stddev>1.0</stddev>
            </noise></vertical>
          </position_sensing>
          <velocity_sensing>
            <horizontal><noise type="gaussian">
              <mean>0.0</mean><stddev>0.1</stddev>
            </noise></horizontal>
            <vertical><noise type="gaussian">
              <mean>0.0</mean><stddev>0.2</stddev>
            </noise></vertical>
          </velocity_sensing>
        </navsat>
        <topic>navsat</topic>
      </sensor>

      <!-- ── Barometer (air pressure) ────────────────────────────────── -->
      <sensor name="air_pressure_sensor" type="air_pressure">
        <always_on>true</always_on>
        <update_rate>50</update_rate>
        <air_pressure>
          <reference_altitude>0</reference_altitude>
          <pressure><noise type="gaussian">
            <mean>0.0</mean><stddev>5.0</stddev>
          </noise></pressure>
        </air_pressure>
        <topic>air_pressure</topic>
      </sensor>

      <!-- ── Magnetometer ────────────────────────────────────────────── -->
      <sensor name="magnetometer_sensor" type="magnetometer">
        <always_on>true</always_on>
        <update_rate>50</update_rate>
        <magnetometer>
          <x><noise type="gaussian">
            <mean>0.0</mean><stddev>0.001</stddev>
          </noise></x>
          <y><noise type="gaussian">
            <mean>0.0</mean><stddev>0.001</stddev>
          </noise></y>
          <z><noise type="gaussian">
            <mean>0.0</mean><stddev>0.001</stddev>
          </noise></z>
        </magnetometer>
        <topic>magnetometer</topic>
      </sensor>

      <!-- ── Downward-facing camera ──────────────────────────────────── -->
      <sensor name="camera_sensor" type="camera">
        <pose>0 0 -0.05 0 1.5708 0</pose>
        <always_on>true</always_on>
        <update_rate>30</update_rate>
        <camera>
          <horizontal_fov>1.5708</horizontal_fov>
          <image>
            <width>640</width>
            <height>480</height>
            <format>R8G8B8</format>
          </image>
          <clip>
            <near>0.1</near>
            <far>100</far>
          </clip>
        </camera>
        <topic>camera</topic>
      </sensor>

      <!-- ── Depth camera ────────────────────────────────────────────── -->
      <sensor name="depth_camera_sensor" type="depth_camera">
        <pose>0.12 0 0 0 0 0</pose>
        <always_on>true</always_on>
        <update_rate>15</update_rate>
        <camera>
          <horizontal_fov>1.2217</horizontal_fov>
          <image>
            <width>320</width>
            <height>240</height>
            <format>R_FLOAT32</format>
          </image>
          <clip>
            <near>0.2</near>
            <far>20</far>
          </clip>
        </camera>
        <topic>depth_camera</topic>
      </sensor>

      <!-- ── 2D LiDAR ───────────────────────────────────────────────── -->
      <sensor name="lidar_sensor" type="gpu_lidar">
        <pose>0 0 0.05 0 0 0</pose>
        <always_on>true</always_on>
        <update_rate>10</update_rate>
        <lidar>
          <scan>
            <horizontal>
              <samples>360</samples>
              <resolution>1</resolution>
              <min_angle>-3.14159</min_angle>
              <max_angle>3.14159</max_angle>
            </horizontal>
            <vertical>
              <samples>1</samples>
              <resolution>1</resolution>
              <min_angle>0</min_angle>
              <max_angle>0</max_angle>
            </vertical>
          </scan>
          <range>
            <min>0.1</min>
            <max>30.0</max>
            <resolution>0.01</resolution>
          </range>
          <noise type="gaussian">
            <mean>0.0</mean>
            <stddev>0.02</stddev>
          </noise>
        </lidar>
        <topic>lidar</topic>
      </sensor>

    </link>

    <!-- ── Motor visuals (propeller discs) ───────────────────────────── -->
    <!-- Front-Right motor (CW) -->
    <link name="rotor_fr">
      <pose>0.18 -0.18 0.025 0 0 0</pose>
      <inertial>
        <mass>0.025</mass>
        <inertia>
          <ixx>0.000025</ixx><iyy>0.000025</iyy><izz>0.00005</izz>
          <ixy>0</ixy><ixz>0</ixz><iyz>0</iyz>
        </inertia>
      </inertial>
      <visual name="visual">
        <geometry><cylinder><radius>0.1</radius><length>0.005</length></cylinder></geometry>
        <material>
          <ambient>0.1 0.1 0.1 0.5</ambient>
          <diffuse>0.15 0.15 0.15 0.5</diffuse>
        </material>
      </visual>
    </link>

    <!-- Front-Left motor (CCW) -->
    <link name="rotor_fl">
      <pose>0.18 0.18 0.025 0 0 0</pose>
      <inertial>
        <mass>0.025</mass>
        <inertia>
          <ixx>0.000025</ixx><iyy>0.000025</iyy><izz>0.00005</izz>
          <ixy>0</ixy><ixz>0</ixz><iyz>0</iyz>
        </inertia>
      </inertial>
      <visual name="visual">
        <geometry><cylinder><radius>0.1</radius><length>0.005</length></cylinder></geometry>
        <material>
          <ambient>0.1 0.1 0.1 0.5</ambient>
          <diffuse>0.15 0.15 0.15 0.5</diffuse>
        </material>
      </visual>
    </link>

    <!-- Rear-Left motor (CW) -->
    <link name="rotor_rl">
      <pose>-0.18 0.18 0.025 0 0 0</pose>
      <inertial>
        <mass>0.025</mass>
        <inertia>
          <ixx>0.000025</ixx><iyy>0.000025</iyy><izz>0.00005</izz>
          <ixy>0</ixy><ixz>0</ixz><iyz>0</iyz>
        </inertia>
      </inertial>
      <visual name="visual">
        <geometry><cylinder><radius>0.1</radius><length>0.005</length></cylinder></geometry>
        <material>
          <ambient>0.1 0.1 0.1 0.5</ambient>
          <diffuse>0.15 0.15 0.15 0.5</diffuse>
        </material>
      </visual>
    </link>

    <!-- Rear-Right motor (CCW) -->
    <link name="rotor_rr">
      <pose>-0.18 -0.18 0.025 0 0 0</pose>
      <inertial>
        <mass>0.025</mass>
        <inertia>
          <ixx>0.000025</ixx><iyy>0.000025</iyy><izz>0.00005</izz>
          <ixy>0</ixy><ixz>0</ixz><iyz>0</iyz>
        </inertia>
      </inertial>
      <visual name="visual">
        <geometry><cylinder><radius>0.1</radius><length>0.005</length></cylinder></geometry>
        <material>
          <ambient>0.1 0.1 0.1 0.5</ambient>
          <diffuse>0.15 0.15 0.15 0.5</diffuse>
        </material>
      </visual>
    </link>

    <!-- ── Rotor joints ──────────────────────────────────────────────── -->
    <joint name="rotor_fr_joint" type="revolute">
      <parent>base_link</parent>
      <child>rotor_fr</child>
      <axis><xyz>0 0 1</xyz><limit><lower>-1e16</lower><upper>1e16</upper></limit></axis>
    </joint>
    <joint name="rotor_fl_joint" type="revolute">
      <parent>base_link</parent>
      <child>rotor_fl</child>
      <axis><xyz>0 0 1</xyz><limit><lower>-1e16</lower><upper>1e16</upper></limit></axis>
    </joint>
    <joint name="rotor_rl_joint" type="revolute">
      <parent>base_link</parent>
      <child>rotor_rl</child>
      <axis><xyz>0 0 1</xyz><limit><lower>-1e16</lower><upper>1e16</upper></limit></axis>
    </joint>
    <joint name="rotor_rr_joint" type="revolute">
      <parent>base_link</parent>
      <child>rotor_rr</child>
      <axis><xyz>0 0 1</xyz><limit><lower>-1e16</lower><upper>1e16</upper></limit></axis>
    </joint>

  </model>
</sdf>
